Workbook
Name _Toc424070724: 'Rate of Growth by age grp'!#REF!

Sheet MYPE by pop grp and sex
A2: Population group | B2: Male | D2: Female | F2: Total
B3: Number | C3: % of total population | D3: Number | E3: % of total population | F3: Number | G3: % of total population
A4: African | B4: 25241810 | C4: 81.762514 | D4: 26362566 | E4: 81.798063 | F4: 51604376 | G4: 81.780671
A5: Coloured | B5: 2612840 | C5: 8.463433 | D5: 2731273 | E5: 8.4746242 | F5: 5344113 | G5: 8.4691489
A6: Indian/Asian | B6: 846674 | C6: 2.742521 | D6: 808297 | E6: 2.5079929 | F6: 1654971 | G6: 2.6227357
A7: White | B7: 2170782 | C7: 7.031532 | D7: 2326703 | E7: 7.2193199 | F7: 4497485 | G7: 7.1274448
A8: Total | B8: 30872106 | C8: 100,0 | D8: 32228839 | E8: 100,0 | F8: 63100945 | G8: 100,0
A9: in thousands
A10: =A4 -> African | B10: =ROUND(B4/1000,1) -> 25241.8 | C10: =C4 -> 81.762514 | D10: =ROUND(D4/1000,1) -> 26362.6 | E10: =E4 -> 81.798063 | F10: =ROUND(F4/1000,1) -> 51604.4 | G10: =G4 -> 81.780671
A11: =A5 -> Coloured | B11: =ROUND(B5/1000,1) -> 2612.8 | C11: =C5 -> 8.463433 | D11: =ROUND(D5/1000,1) -> 2731.3 | E11: =E5 -> 8.4746242 | F11: =ROUND(F5/1000,1) -> 5344.1 | G11: =G5 -> 8.4691489
A12: =A6 -> Indian/Asian | B12: =ROUND(B6/1000,1) -> 846.7 | C12: =C6 -> 2.742521 | D12: =ROUND(D6/1000,1) -> 808.3 | E12: =E6 -> 2.5079929 | F12: =ROUND(F6/1000,1) -> 1655 | G12: =G6 -> 2.6227357
A13: =A7 -> White | B13: =ROUND(B7/1000,1) -> 2170.8 | C13: =C7 -> 7.031532 | D13: =ROUND(D7/1000,1) -> 2326.7 | E13: =E7 -> 7.2193199 | F13: =ROUND(F7/1000,1) -> 4497.5 | G13: =G7 -> 7.1274448
B14: =ROUND(B8/1000,1) -> 30872.1 | C14: =C8 -> 100,0 | D14: =ROUND(D8/1000,1) -> 32228.8 | E14: =E8 -> 100,0 | F14: =ROUND(F8/1000,1) -> 63100.9 | G14: =G8 -> 100,0
A16: male | B16: =B8/F8*100 -> 48.92495
A17: female | B17: =D8/F8*100 -> 51.07505
D18: .. | J18: ,

Sheet Total Fertilty Rate
A1: Year | B1: TFR
A2: 2002 | B2: 2.55
A3: 2003 | B3: 2.48
A4: 2004 | B4: 2.62
A5: 2005 | B5: 2.74
A6: 2006 | B6: 2.77
A7: 2007 | B7: 2.77
A8: 2008 | B8: 2.78
A9: 2009 | B9: 2.7
A10: 2010 | B10: 2.62
A11: 2011 | B11: 2.6
A12: 2012 | B12: 2.56
A13: 2013 | B13: 2.49
... A25: 2025 | B25: 2.21

Sheet MYPE by province
C3: Population estimate | D3: % of total population
B4: Eastern Cape | C4: 7090788 | D4: 11.237214
B5: Free State | C5: 3039834 | D5: 4.8174136
B6: Gauteng | C6: 16104933 | D6: 25.522492
B7: KwaZulu-Natal | C7: 12232247 | D7: 19.385204
B8: Limpopo | C8: 6366192 | D8: 10.088901
B9: Mpumalanga | C9: 5076133 | D9: 8.0444645
B10: Northern Cape | C10: 1379183 | D10: 2.1856771
B11: North West | C11: 4183947 | D11: 6.6305609
B12: Western Cape | C12: 7627688 | D12: 12.088073
B13: Total | C13: 63100945 | D13: 100

Sheet International Net migration
C1: African | D1: Indian/Asian | E1: White | F1: Net Internationl Migration
B2: 1985-2000 | C2: 718432 | D2: 53672 | E2: -202868 | F2: 569236
B3: 2001-2006 | C3: 619509 | D3: 35562 | E3: -99574 | F3: 555497
B4: 2006-2011 | C4: 878851 | D4: 53047 | E4: -106787 | F4: 825111
B5: 2011-2016 | C5: 1100815 | D5: 65431 | E5: -111346 | F5: 1054900
B6: 2016-2021 | C6: 956984 | D6: 60700 | E6: -90957 | F6: 926727
B7: 2021-2026 | C7: 903697 | D7: 56547 | E7: -94898 | F7: 865346

Sheet Mortality Indicators over time
C1: Life Expectancy
B2: CBR | C2: Male | D2: Female | E2: Total | F2: IMR | G2: U5MR | H2: CDR | I2: RNI
A3: 2002 | B3: 21.2 | C3: 52.7 | D3: 57.6 | E3: 55.2 | F3: 61.9 | G3: 79.9 | H3: 12.883621 | I3: 0.81872948
A4: 2003 | B4: 20.7 | C4: 52.1 | D4: 57 | E4: 54.6 | F4: 63.4 | G4: 80.2 | H4: 13.339578 | I4: 0.72581787
A5: 2004 | B5: 22 | C5: 51.9 | D5: 56.5 | E5: 54.3 | F5: 63.6 | G5: 80 | H5: 13.642969 | I5: 0.82614698
A6: 2005 | B6: 23.1 | C6: 51.9 | D6: 56.2 | E6: 54.1 | F6: 61.8 | G6: 79.5 | H6: 13.824855 | I6: 0.91323959
A7: 2006 | B7: 23.5 | C7: 51.8 | D7: 56.5 | E7: 54.2 | F7: 61.8 | G7: 79.6 | H7: 13.818528 | I7: 0.95143076
A8: 2007 | B8: 23.7 | C8: 52.6 | D8: 57.1 | E8: 54.9 | F8: 55.1 | G8: 76.2 | H8: 13.568314 | I8: 0.99314581
A9: 2008 | B9: 23.9 | C9: 54 | D9: 58.8 | E9: 56.5 | F9: 49.3 | G9: 66.6 | H9: 12.832144 | I9: 1.0855151
A10: 2009 | B10: 23.2 | C10: 55 | D10: 60.3 | E10: 57.7 | F10: 45.1 | G10: 57.9 | H10: 12.229738 | I10: 1.0839019
A11: 2010 | B11: 22.6 | C11: 55.9 | D11: 61.1 | E11: 58.6 | F11: 43.8 | G11: 53.9 | H11: 11.819757 | I11: 1.0637937
A12: 2011 | B12: 22.5 | C12: 57 | D12: 63 | E12: 60.1 | F12: 38.7 | G12: 46.5 | H12: 11.075602 | I12: 1.1245402
A13: 2012 | B13: 22.2 | C13: 59.4 | D13: 65 | E13: 62.3 | F13: 32.3 | G13: 39.7 | H13: 9.9423511 | I13: 1.2103665
A14: 2013 | B14: 21.5 | C14: 59.9 | D14: 65.7 | E14: 62.9 | F14: 32.9 | G14: 38.7 | H14: 9.7004735 | I14: 1.1677447
... A26: 2025 | B26: 17.8 | C26: 64 | D26: 69.6 | E26: 66.9 | F26: 23.1 | G26: 26.1 | H26: 8.8297093 | I26: 0.88852077

Sheet Births and deaths over time
B2: Number of Births | C2: Number of deaths | D2: Number of AIDS related deaths | E2: Percentage of AIDS deaths
A3: 2002 | B3: 982627 | C3: 600819 | D3: 216649 | E3: 36.058946
A4: 2003 | B4: 969589 | C4: 627928 | D4: 242358 | E4: 38.596463
A5: 2004 | B5: 1042137 | C5: 649085 | D5: 253597 | E5: 39.069922
A6: 2005 | B6: 1105210 | C6: 665558 | D6: 272508 | E6: 40.94429
A7: 2006 | B7: 1137244 | C7: 673516 | D7: 275348 | E7: 40.882177
A8: 2007 | B8: 1160263 | C8: 669914 | D8: 252392 | E8: 37.675284
A9: 2008 | B9: 1185987 | C9: 642486 | D9: 215337 | E9: 33.516217
A10: 2009 | B10: 1171502 | C10: 621064 | D10: 186697 | E10: 30.060831
A11: 2010 | B11: 1156746 | C11: 608810 | D11: 169076 | E11: 27.771554
A12: 2011 | B12: 1167060 | C12: 579091 | D12: 140809 | E12: 24.315522
A13: 2012 | B13: 1171207 | C13: 528193 | D13: 114252 | E13: 21.63073
A14: 2013 | B14: 1153570 | C14: 523445 | D14: 104330 | E14: 19.931416
... A26: 2025 | B26: 1117840 | C26: 557164 | D26: 77639 | E26: 13.934676

Sheet HIV Estimates over time
B1: Prevalence
B2: Women 15-49' | C2: Adults 15-49 | D2: Youth 15-24 | E2: Incidence 15-49 | F2: Total population | G2: Number of people living with HIV
A3: 2002 | B3: 17.82 | C3: 14.86 | D3: 10.22 | E3: 1.85 | F3: 8.79 | G3: 4.1
A4: 2003 | B4: 18.37 | C4: 15.26 | D4: 10.05 | E4: 1.77 | F4: 9.16 | G4: 4.31
A5: 2004 | B5: 18.82 | C5: 15.57 | D5: 9.85 | E5: 1.69 | F5: 9.47 | G5: 4.51
A6: 2005 | B6: 19.2 | C6: 15.8 | D6: 9.66 | E6: 1.62 | F6: 9.72 | G6: 4.68
A7: 2006 | B7: 19.53 | C7: 15.98 | D7: 9.43 | E7: 1.54 | F7: 9.93 | G7: 4.84
A8: 2007 | B8: 19.87 | C8: 16.17 | D8: 9.19 | E8: 1.46 | F8: 10.1 | G8: 4.99
A9: 2008 | B9: 20.24 | C9: 16.39 | D9: 8.97 | E9: 1.39 | F9: 10.3 | G9: 5.16
A10: 2009 | B10: 20.66 | C10: 16.64 | D10: 8.81 | E10: 1.35 | F10: 10.49 | G10: 5.32
A11: 2010 | B11: 21.09 | C11: 16.93 | D11: 8.71 | E11: 1.33 | F11: 10.7 | G11: 5.51
A12: 2011 | B12: 21.51 | C12: 17.22 | D12: 8.51 | E12: 1.25 | F12: 10.9 | G12: 5.7
A13: 2012 | B13: 22.01 | C13: 17.57 | D13: 8.4 | E13: 1.24 | F13: 11.14 | G13: 5.92
A14: 2013 | B14: 22.4 | C14: 17.83 | D14: 8.18 | E14: 1.1 | F14: 11.33 | G14: 6.11
... A26: 2025 | B26: 23.38 | C26: 18.13 | D26: 6.84 | E26: 0.94 | F26: 12.92 | G26: 8.15

Sheet Rate of Growth by age grp
C1: Children 0-14 | D1: Youth 15-24 | E1: adults 25-59 | F1: Elderly 60+ | G1: Total
B2: 2002–2003 | C2: -1.53 | D2: 3.48 | E2: 1.5 | F2: 1.65 | G2: 0.94
B3: 2003–2004 | C3: -1.13 | D3: 3.34 | E3: 1.48 | F3: 1.77 | G3: 1.06
B4: 2004–2005 | C4: -0.59 | D4: 2.78 | E4: 1.55 | F4: 1.95 | G4: 1.18
B5: 2005–2006 | C5: -0.25 | D5: 1.86 | E5: 1.84 | F5: 2.18 | G5: 1.23
B6: 2006–2007 | C6: 0.04 | D6: 1.4 | E6: 1.97 | F6: 2.26 | G6: 1.29
B7: 2007–2008 | C7: 0.4 | D7: 0.98 | E7: 2.15 | F7: 2.38 | G7: 1.4
B8: 2008–2009 | C8: 0.54 | D8: 0.57 | E8: 2.26 | F8: 2.51 | G8: 1.42
B9: 2009–2010 | C9: 0.62 | D9: 0.15 | E9: 2.37 | F9: 2.62 | G9: 1.42
B10: 2010–2011 | C10: 0.89 | D10: -0.98 | E10: 2.88 | F10: 2.76 | G10: 1.5
B11: 2011–2012 | C11: 1.21 | D11: -1.33 | E11: 2.94 | F11: 3.05 | G11: 1.59
B12: 2012–2013 | C12: 1.29 | D12: -1.67 | E12: 2.9 | F12: 3.03 | G12: 1.56
B13: 2013–2014 | C13: 1.34 | D13: -1.62 | E13: 2.86 | F13: 3.17 | G13: 1.61
... B24: 2024-2025 | C24: -0.06 | D24: 1.88 | E24: 1.37 | F24: 2.83 | G24: 1.23

Sheet MYPE by pop grp age and sex
B1: Black African | E1: Coloured | H1: Indian/Asian | K1: White | N1: RSA
B2: Male | C2: Female | D2: Total | E2: Male | F2: Female | G2: Total | H2: Male | I2: Female | J2: Total | K2: Male | L2: Female | M2: Total | N2: Male | O2: Female | P2: Total
A3: 0-4 | B3: 2451896 | C3: 2395247 | D3: 4847143 | E3: 215792 | F3: 208908 | G3: 424700 | H3: 41091 | I3: 39644 | J3: 80735 | K3: 81349 | L3: 79074 | M3: 160423 | N3: 2790128 | O3: 2722873 | P3: 5513001
A4: 5-9 | B4: 2379725 | C4: 2325352 | D4: 4705077 | E4: 206033 | F4: 199905 | G4: 405938 | H4: 46136 | I4: 44286 | J4: 90422 | K4: 98392 | L4: 95710 | M4: 194102 | N4: 2730286 | O4: 2665253 | P4: 5395539
A5: 10-14 | B5: 2438375 | C5: 2394177 | D5: 4832552 | E5: 219299 | F5: 213442 | G5: 432741 | H5: 51221 | I5: 48833 | J5: 100054 | K5: 122383 | L5: 119236 | M5: 241619 | N5: 2831278 | O5: 2775688 | P5: 5606966
A6: 15-19 | B6: 2360190 | C6: 2335785 | D6: 4695975 | E6: 227906 | F6: 222649 | G6: 450555 | H6: 49882 | I6: 47203 | J6: 97085 | K6: 129454 | L6: 127166 | M6: 256620 | N6: 2767432 | O6: 2732803 | P6: 5500235
A7: 20-24 | B7: 2037310 | C7: 2026556 | D7: 4063866 | E7: 204384 | F7: 200308 | G7: 404692 | H7: 52484 | I7: 45386 | J7: 97870 | K7: 113236 | L7: 113377 | M7: 226613 | N7: 2407414 | O7: 2385627 | P7: 4793041
A8: 25-29 | B8: 2106592 | C8: 2087136 | D8: 4193728 | E8: 210971 | F8: 206907 | G8: 417878 | H8: 66310 | I8: 53457 | J8: 119767 | K8: 117028 | L8: 117826 | M8: 234854 | N8: 2500901 | O8: 2465326 | P8: 4966227
A9: 30-34 | B9: 2336934 | C9: 2335985 | D9: 4672919 | E9: 216605 | F9: 212737 | G9: 429342 | H9: 80870 | I9: 65051 | J9: 145921 | K9: 127621 | L9: 128470 | M9: 256091 | N9: 2762030 | O9: 2742243 | P9: 5504273
A10: 35-39 | B10: 2393085 | C10: 2374346 | D10: 4767431 | E10: 212531 | F10: 208566 | G10: 421097 | H10: 85476 | I10: 70803 | J10: 156279 | K10: 144904 | L10: 143910 | M10: 288814 | N10: 2835996 | O10: 2797625 | P10: 5633621
A11: 40-44 | B11: 1910347 | C11: 1885024 | D11: 3795371 | E11: 184610 | F11: 187848 | G11: 372458 | H11: 83993 | I11: 70997 | J11: 154990 | K11: 151539 | L11: 151734 | M11: 303273 | N11: 2330489 | O11: 2295603 | P11: 4626092
A12: 45-49 | B12: 1397540 | C12: 1395928 | D12: 2793468 | E12: 153007 | F12: 152138 | G12: 305145 | H12: 69428 | I12: 60433 | J12: 129861 | K12: 147616 | L12: 153536 | M12: 301152 | N12: 1767591 | O12: 1762035 | P12: 3529626
A13: 50-54 | B13: 1073536 | C13: 1131956 | D13: 2205492 | E13: 146799 | F13: 152900 | G13: 299699 | H13: 60002 | I13: 55757 | J13: 115759 | K13: 169504 | L13: 177564 | M13: 347068 | N13: 1449841 | O13: 1518177 | P13: 2968018
A14: 55-59 | B14: 762443 | C14: 976786 | D14: 1739229 | E14: 132715 | F14: 156328 | G14: 289043 | H14: 49055 | I14: 50044 | J14: 99099 | K14: 160486 | L14: 171363 | M14: 331849 | N14: 1104699 | O14: 1354521 | P14: 2459220
... A19: 80+ | B19: 87320 | C19: 248174 | D19: 335494 | E19: 16486 | F19: 42153 | G19: 58639 | H19: 8853 | I19: 22245 | J19: 31098 | K19: 110375 | L19: 169442 | M19: 279817 | N19: 223034 | O19: 482014 | P19: 705048
B20: 25241810 | C20: 26362566 | D20: 51604376 | E20: 2612840 | F20: 2731273 | G20: 5344113 | H20: 846674 | I20: 808297 | J20: 1654971 | K20: 2170782 | L20: 2326703 | M20: 4497485 | N20: 30872106 | O20: 32228839 | P20: 63100945
A22: In thousands | B22: =B1 -> Black African | E22: =E1 -> Coloured | H22: =H1 -> Indian/Asian | K22: =K1 -> White | N22: =N1 -> RSA
A23: =A2 -> 0 | B23: =B2 -> Male | C23: =C2 -> Female | D23: =D2 -> Total | E23: =E2 -> Male | F23: =F2 -> Female | G23: =G2 -> Total | H23: =H2 -> Male | ... P23: =P2 -> Total
A24: =A3 -> 0-4 | B24: =ROUND(B3/1000,1) -> 2451.9 | C24: =ROUND(C3/1000,1) -> 2395.2 | D24: =ROUND(D3/1000,1) -> 4847.1 | E24: =ROUND(E3/1000,1) -> 215.8 | F24: =ROUND(F3/1000,1) -> 208.9 | G24: =ROUND(G3/1000,1) -> 424.7 | H24: =ROUND(H3/1000,1) -> 41.1 | I24: =ROUND(I3/1000,1) -> 39.6 | ... P24: =ROUND(P3/1000,1) -> 5513
A25: =A4 -> 5-9 | B25: =ROUND(B4/1000,1) -> 2379.7 | C25: =ROUND(C4/1000,1) -> 2325.4 | D25: =ROUND(D4/1000,1) -> 4705.1 | E25: =ROUND(E4/1000,1) -> 206 | F25: =ROUND(F4/1000,1) -> 199.9 | G25: =ROUND(G4/1000,1) -> 405.9 | H25: =ROUND(H4/1000,1) -> 46.1 | I25: =ROUND(I4/1000,1) -> 44.3 | ... P25: =ROUND(P4/1000,1) -> 5395.5
A26: =A5 -> 10-14 | B26: =ROUND(B5/1000,1) -> 2438.4 | C26: =ROUND(C5/1000,1) -> 2394.2 | D26: =ROUND(D5/1000,1) -> 4832.6 | E26: =ROUND(E5/1000,1) -> 219.3 | F26: =ROUND(F5/1000,1) -> 213.4 | G26: =ROUND(G5/1000,1) -> 432.7 | H26: =ROUND(H5/1000,1) -> 51.2 | I26: =ROUND(I5/1000,1) -> 48.8 | ... P26: =ROUND(P5/1000,1) -> 5607
A27: =A6 -> 15-19 | B27: =ROUND(B6/1000,1) -> 2360.2 | C27: =ROUND(C6/1000,1) -> 2335.8 | D27: =ROUND(D6/1000,1) -> 4696 | E27: =ROUND(E6/1000,1) -> 227.9 | F27: =ROUND(F6/1000,1) -> 222.6 | G27: =ROUND(G6/1000,1) -> 450.6 | H27: =ROUND(H6/1000,1) -> 49.9 | I27: =ROUND(I6/1000,1) -> 47.2 | ... P27: =ROUND(P6/1000,1) -> 5500.2
A28: =A7 -> 20-24 | B28: =ROUND(B7/1000,1) -> 2037.3 | C28: =ROUND(C7/1000,1) -> 2026.6 | D28: =ROUND(D7/1000,1) -> 4063.9 | E28: =ROUND(E7/1000,1) -> 204.4 | F28: =ROUND(F7/1000,1) -> 200.3 | G28: =ROUND(G7/1000,1) -> 404.7 | H28: =ROUND(H7/1000,1) -> 52.5 | I28: =ROUND(I7/1000,1) -> 45.4 | ... P28: =ROUND(P7/1000,1) -> 4793
A29: =A8 -> 25-29 | B29: =ROUND(B8/1000,1) -> 2106.6 | C29: =ROUND(C8/1000,1) -> 2087.1 | D29: =ROUND(D8/1000,1) -> 4193.7 | E29: =ROUND(E8/1000,1) -> 211 | F29: =ROUND(F8/1000,1) -> 206.9 | G29: =ROUND(G8/1000,1) -> 417.9 | H29: =ROUND(H8/1000,1) -> 66.3 | I29: =ROUND(I8/1000,1) -> 53.5 | ... P29: =ROUND(P8/1000,1) -> 4966.2
A30: =A9 -> 30-34 | B30: =ROUND(B9/1000,1) -> 2336.9 | C30: =ROUND(C9/1000,1) -> 2336 | D30: =ROUND(D9/1000,1) -> 4672.9 | E30: =ROUND(E9/1000,1) -> 216.6 | F30: =ROUND(F9/1000,1) -> 212.7 | G30: =ROUND(G9/1000,1) -> 429.3 | H30: =ROUND(H9/1000,1) -> 80.9 | I30: =ROUND(I9/1000,1) -> 65.1 | ... P30: =ROUND(P9/1000,1) -> 5504.3
A31: =A10 -> 35-39 | B31: =ROUND(B10/1000,1) -> 2393.1 | C31: =ROUND(C10/1000,1) -> 2374.3 | D31: =ROUND(D10/1000,1) -> 4767.4 | E31: =ROUND(E10/1000,1) -> 212.5 | F31: =ROUND(F10/1000,1) -> 208.6 | G31: =ROUND(G10/1000,1) -> 421.1 | H31: =ROUND(H10/1000,1) -> 85.5 | I31: =ROUND(I10/1000,1) -> 70.8 | ... P31: =ROUND(P10/1000,1) -> 5633.6
A32: =A11 -> 40-44 | B32: =ROUND(B11/1000,1) -> 1910.3 | C32: =ROUND(C11/1000,1) -> 1885 | D32: =ROUND(D11/1000,1) -> 3795.4 | E32: =ROUND(E11/1000,1) -> 184.6 | F32: =ROUND(F11/1000,1) -> 187.8 | G32: =ROUND(G11/1000,1) -> 372.5 | H32: =ROUND(H11/1000,1) -> 84 | I32: =ROUND(I11/1000,1) -> 71 | ... P32: =ROUND(P11/1000,1) -> 4626.1
A33: =A12 -> 45-49 | B33: =ROUND(B12/1000,1) -> 1397.5 | C33: =ROUND(C12/1000,1) -> 1395.9 | D33: =ROUND(D12/1000,1) -> 2793.5 | E33: =ROUND(E12/1000,1) -> 153 | F33: =ROUND(F12/1000,1) -> 152.1 | G33: =ROUND(G12/1000,1) -> 305.1 | H33: =ROUND(H12/1000,1) -> 69.4 | I33: =ROUND(I12/1000,1) -> 60.4 | ... P33: =ROUND(P12/1000,1) -> 3529.6
A34: =A13 -> 50-54 | B34: =ROUND(B13/1000,1) -> 1073.5 | C34: =ROUND(C13/1000,1) -> 1132 | D34: =ROUND(D13/1000,1) -> 2205.5 | E34: =ROUND(E13/1000,1) -> 146.8 | F34: =ROUND(F13/1000,1) -> 152.9 | G34: =ROUND(G13/1000,1) -> 299.7 | H34: =ROUND(H13/1000,1) -> 60 | I34: =ROUND(I13/1000,1) -> 55.8 | ... P34: =ROUND(P13/1000,1) -> 2968
A35: =A14 -> 55-59 | B35: =ROUND(B14/1000,1) -> 762.4 | C35: =ROUND(C14/1000,1) -> 976.8 | D35: =ROUND(D14/1000,1) -> 1739.2 | E35: =ROUND(E14/1000,1) -> 132.7 | F35: =ROUND(F14/1000,1) -> 156.3 | G35: =ROUND(G14/1000,1) -> 289 | H35: =ROUND(H14/1000,1) -> 49.1 | I35: =ROUND(I14/1000,1) -> 50 | ... P35: =ROUND(P14/1000,1) -> 2459.2
... A40: =A19 -> 80+ | B40: =ROUND(B19/1000,1) -> 87.3 | C40: =ROUND(C19/1000,1) -> 248.2 | D40: =ROUND(D19/1000,1) -> 335.5 | E40: =ROUND(E19/1000,1) -> 16.5 | F40: =ROUND(F19/1000,1) -> 42.2 | G40: =ROUND(G19/1000,1) -> 58.6 | H40: =ROUND(H19/1000,1) -> 8.9 | I40: =ROUND(I19/1000,1) -> 22.2 | ... P40: =ROUND(P19/1000,1) -> 705
A41: =A20 -> 0 | B41: =(B20/1000) -> 25241.81 | C41: =(C20/1000) -> 26362.566 | D41: =(D20/1000) -> 51604.376 | E41: =(E20/1000) -> 2612.84 | F41: =(F20/1000) -> 2731.273 | G41: =(G20/1000) -> 5344.113 | H41: =(H20/1000) -> 846.674 | I41: =(I20/1000) -> 808.297 | ... P41: =(P20/1000) -> 63100.945

Sheet inter provincial migration
A1: Table 11: Estimated provincial migration streams, 2006–2011
A2: Province in 2006 | B2: Province in 2011
B3: EC | C3: FS | D3: GP | E3: KZN | F3: LIM | G3: MP | H3: NC | I3: NW | J3: WC | K3: Out-migrants | L3: In-migrants | M3: Net migration
A4: EC | B4: 0 | C4: 13355 | D4: 149659 | E4: 100765 | F4: 14337 | G4: 17245 | H4: 8292 | I4: 38653 | J4: 167944 | K4: 510251 | L4: 170459 | M4: -339791
A5: FS | B5: 8168 | C5: 0 | D5: 79372 | E5: 7620 | F5: 6435 | G5: 10430 | H5: 8764 | I5: 23118 | J5: 11805 | K5: 155711 | L5: 121739 | M5: -33972
A6: GP | B6: 45054 | C6: 35138 | D6: 0 | E6: 73131 | F6: 96378 | G6: 86576 | H6: 10350 | I6: 66329 | J6: 102984 | K6: 515941 | L6: 1426633 | M6: 910692
A7: KZN | B7: 23809 | C7: 11520 | D7: 209240 | E7: 0 | F7: 8957 | G7: 34276 | H7: 8032 | I7: 10892 | J7: 31138 | K7: 337865 | L7: 284698 | M7: -53167
A8: LIM | B8: 4231 | C8: 5495 | D8: 327379 | E8: 7768 | F8: 0 | G8: 44891 | H8: 2445 | I8: 30595 | J8: 10729 | K8: 433534 | L8: 261997 | M8: -171537
A9: MP | B9: 4619 | C9: 4788 | D9: 122937 | E9: 11601 | F9: 21527 | G9: 0 | H9: 2121 | I9: 12297 | J9: 8987 | K9: 188879 | L9: 273469 | M9: 84590
A10: NC | B10: 4150 | C10: 8287 | D10: 15557 | E10: 5307 | F10: 2476 | G10: 4206 | H10: 0 | I10: 11885 | J10: 17051 | K10: 68919 | L10: 77201 | M10: 8282
A11: NW | B11: 4367 | C11: 9933 | D11: 77793 | E11: 5152 | F11: 16824 | G11: 10046 | H11: 19867 | I11: 0 | J11: 7669 | K11: 151651 | L11: 264657 | M11: 113006
A12: WC | B12: 44766 | C12: 6986 | D12: 54108 | E12: 11409 | F12: 5049 | G12: 6326 | H12: 11167 | I12: 7264 | J12: 0 | K12: 147075 | L12: 454083 | M12: 307009
A13: Outside SA (net migration) | B13: 31295 | C13: 26237 | D13: 390587 | E13: 61946 | F13: 90013 | G13: 59472 | H13: 6163 | I13: 63624 | J13: 95775
A15: Table 12: Estimated provincial migration streams, 2011–2016
A16: Province in 2011 | B16: Province in 2016
B17: EC | C17: FS | D17: GP | E17: KZN | F17: LIM | G17: MP | H17: NC | I17: NW | J17: WC | K17: Out-migrants | L17: In-migrants | M17: Net migration
A18: EC | B18: 0 | C18: 14006 | D18: 136484 | E18: 104121 | F18: 14759 | G18: 17473 | H18: 8570 | I18: 30742 | J18: 168054 | K18: 494208 | L18: 187618 | M18: -306590
A19: FS | B19: 8400 | C19: 0 | D19: 74316 | E19: 7844 | F19: 6626 | G19: 10738 | H19: 9100 | I19: 23791 | J19: 12170 | K19: 152985 | L19: 140444 | M19: -12541
A20: GP | B20: 45497 | C20: 40261 | D20: 0 | E20: 91058 | F20: 91790 | G20: 82500 | H20: 11116 | I20: 80331 | J20: 99659 | K20: 542213 | L20: 1530244 | M20: 988031
A21: KZN | B21: 25885 | C21: 13016 | D21: 209802 | E21: 0 | F21: 9287 | G21: 37023 | H21: 8581 | I21: 11931 | J21: 34225 | K21: 349750 | L21: 330660 | M21: -19090
A22: LIM | B22: 4519 | C22: 5867 | D22: 314821 | E22: 8274 | F22: 0 | G22: 47276 | H22: 2582 | I22: 32219 | J22: 11297 | K22: 426855 | L22: 290771 | M22: -136084
A23: MP | B23: 5050 | C23: 5222 | D23: 136099 | E23: 12649 | F23: 23448 | G23: 0 | H23: 2322 | I23: 13419 | J23: 9800 | K23: 208009 | L23: 295632 | M23: 87623
A24: NC | B24: 4421 | C24: 9083 | D24: 17202 | E24: 5798 | F24: 2679 | G24: 4592 | H24: 0 | I24: 12982 | J24: 18200 | K24: 74957 | L24: 84053 | M24: 9096
A25: NW | B25: 4794 | C25: 10872 | D25: 97849 | E25: 5644 | F25: 18402 | G25: 10992 | H25: 21768 | I25: 0 | J25: 8421 | K25: 178742 | L25: 293710 | M25: 114968
A26: WC | B26: 47945 | C26: 7578 | D26: 58566 | E26: 12262 | F26: 5423 | G26: 6827 | H26: 11968 | I26: 7870 | J26: 0 | K26: 158439 | L26: 487927 | M26: 329488
A27: Outside SA (net migration) | B27: 41107 | C27: 34539 | D27: 485104 | E27: 83010 | F27: 118357 | G27: 78210 | H27: 8046 | I27: 80425 | J27: 126101
A29: Table 13: Estimated provincial migration streams, 2016–2021
A30: Province in 2016 | B30: Province in 2021
B31: EC | C31: FS | D31: GP | E31: KZN | F31: LIM | G31: MP | H31: NC | I31: NW | J31: WC | K31: Out-migrants | L31: In-migrants | M31: Net migration
A32: EC | B32: 0 | C32: 14207 | D32: 138562 | E32: 105807 | F32: 14967 | G32: 17721 | H32: 8682 | I32: 20700 | J32: 171202 | K32: 491848 | L32: 196301 | M32: -295548
A33: FS | B33: 8662 | C33: 0 | D33: 76739 | E33: 9263 | F33: 6830 | G33: 11082 | H33: 9393 | I33: 20925 | J33: 13046 | K33: 155940 | L33: 145326 | M33: -10614
A34: GP | B34: 52528 | C34: 44709 | D34: 0 | E34: 103007 | F34: 84479 | G34: 84672 | H34: 11605 | I34: 99596 | J34: 104471 | K34: 585066 | L34: 1445260 | M34: 860194
A35: KZN | B35: 27357 | C35: 13775 | D35: 183386 | E35: 0 | F35: 9824 | G35: 39211 | H35: 9071 | I35: 12635 | J35: 36214 | K35: 331473 | L35: 337076 | M35: 5603
A36: LIM | B36: 4790 | C36: 6217 | D36: 311682 | E36: 8778 | F36: 0 | G36: 50115 | H36: 2741 | I36: 34139 | J36: 12434 | K36: 430894 | L36: 272739 | M36: -158155
A37: MP | B37: 5465 | C37: 5648 | D37: 126427 | E37: 13678 | F37: 25360 | G37: 0 | H37: 2517 | I37: 14526 | J37: 10597 | K37: 204219 | L37: 294411 | M37: 90192
A38: NC | B38: 4691 | C38: 9665 | D38: 18301 | E38: 6155 | F38: 2848 | G38: 4876 | H38: 0 | I38: 13793 | J38: 19357 | K38: 79687 | L38: 87688 | M38: 8001
A39: NW | B39: 5198 | C39: 13047 | D39: 93888 | E39: 5483 | F39: 20611 | G39: 11905 | H39: 23647 | I39: 0 | J39: 9137 | K39: 182918 | L39: 294256 | M39: 111338
A40: WC | B40: 52252 | C40: 8313 | D40: 64346 | E40: 13496 | F40: 5959 | G40: 7514 | H40: 13134 | I40: 8672 | J40: 0 | K40: 173685 | L40: 489402 | M40: 315717
A41: Outside SA (net migration) | B41: 35358 | C41: 29745 | D41: 431929 | E41: 71409 | F41: 101861 | G41: 67315 | H41: 6898 | I41: 69269 | J41: 112943
A44: Table 13: Estimated provincial migration streams, 2021–2026
...

Sheet % distribution of prov overtime
B3: 2002 | C3: 2003 | D3: 2004 | E3: 2005 | F3: 2006 | G3: 2007 | H3: 2008 | I3: 2009 | J3: 2010 | K3: 2011 | L3: 2012 | M3: 2013 | N3: 2014 | O3: 2015 | P3: 2016 | Q3: 2017 | R3: 2018 | S3: 2019 | T3: 2020 | U3: 2021 | V3: 2022 | W3: 2023 | X3: 2024 | Y3: 2025
A4: Eastern Cape | B4: 14.73 | C4: 14.56 | D4: 14.39 | E4: 14.23 | F4: 14.07 | G4: 13.9 | H4: 13.72 | I4: 13.54 | J4: 13.36 | K4: 13.17 | L4: 13 | M4: 12.85 | N4: 12.69 | O4: 12.54 | P4: 12.39 | Q4: 12.26 | R4: 12.12 | S4: 11.99 | T4: 11.85 | U4: 11.73 | V4: 11.6 | W4: 11.48 | X4: 11.36 | Y4: 11.24
A5: Free State | B5: 5.91 | C5: 5.84 | D5: 5.77 | E5: 5.71 | F5: 5.64 | G5: 5.59 | H5: 5.53 | I5: 5.47 | J5: 5.41 | K5: 5.35 | L5: 5.31 | M5: 5.26 | N5: 5.22 | O5: 5.17 | P5: 5.13 | Q5: 5.09 | R5: 5.05 | S5: 5.01 | T5: 4.98 | U5: 4.94 | V5: 4.91 | W5: 4.88 | X5: 4.85 | Y5: 4.82
A6: Gauteng | B6: 19.97 | C6: 20.3 | D6: 20.63 | E6: 20.96 | F6: 21.29 | G6: 21.58 | H6: 21.87 | I6: 22.17 | J6: 22.47 | K6: 22.78 | L6: 23.03 | M6: 23.28 | N6: 23.52 | O6: 23.76 | P6: 24 | Q6: 24.2 | R6: 24.39 | S6: 24.58 | T6: 24.77 | U6: 24.94 | V6: 25.1 | W6: 25.24 | X6: 25.39 | Y6: 25.52
A7: KwaZulu-Natal | B7: 21.23 | C7: 21.1 | D7: 20.97 | E7: 20.84 | F7: 20.7 | G7: 20.58 | H7: 20.46 | I7: 20.35 | J7: 20.24 | K7: 20.14 | L7: 20.07 | M7: 20 | N7: 19.92 | O7: 19.84 | P7: 19.76 | Q7: 19.7 | R7: 19.65 | S7: 19.6 | T7: 19.54 | U7: 19.5 | V7: 19.47 | W7: 19.44 | X7: 19.41 | Y7: 19.39
A8: Limpopo | B8: 11.16 | C8: 11.08 | D8: 11.01 | E8: 10.95 | F8: 10.88 | G8: 10.83 | H8: 10.77 | I8: 10.71 | J8: 10.64 | K8: 10.56 | L8: 10.51 | M8: 10.46 | N8: 10.42 | O8: 10.39 | P8: 10.36 | Q8: 10.34 | R8: 10.3 | S8: 10.27 | T8: 10.23 | U8: 10.2 | V8: 10.17 | W8: 10.14 | X8: 10.11 | Y8: 10.09
A9: Mpumalanga | B9: 7.75 | C9: 7.77 | D9: 7.78 | E9: 7.79 | F9: 7.8 | G9: 7.81 | H9: 7.83 | I9: 7.85 | J9: 7.88 | K9: 7.91 | L9: 7.92 | M9: 7.93 | N9: 7.94 | O9: 7.94 | P9: 7.93 | Q9: 7.94 | R9: 7.95 | S9: 7.97 | T9: 7.98 | U9: 8 | V9: 8.01 | W9: 8.02 | X9: 8.03 | Y9: 8.04
A10: Northern Cape | B10: 2.29 | C10: 2.28 | D10: 2.28 | E10: 2.28 | F10: 2.27 | G10: 2.27 | H10: 2.26 | I10: 2.26 | J10: 2.25 | K10: 2.24 | L10: 2.23 | M10: 2.23 | N10: 2.22 | O10: 2.22 | P10: 2.22 | Q10: 2.21 | R10: 2.21 | S10: 2.21 | T10: 2.2 | U10: 2.2 | V10: 2.19 | W10: 2.19 | X10: 2.19 | Y10: 2.19
A11: North West | B11: 6.35 | C11: 6.36 | D11: 6.37 | E11: 6.38 | F11: 6.4 | G11: 6.42 | H11: 6.44 | I11: 6.45 | J11: 6.46 | K11: 6.47 | L11: 6.48 | M11: 6.5 | N11: 6.51 | O11: 6.52 | P11: 6.53 | Q11: 6.54 | R11: 6.55 | S11: 6.56 | T11: 6.57 | U11: 6.58 | V11: 6.59 | W11: 6.6 | X11: 6.62 | Y11: 6.63
A12: Western Cape | B12: 10.62 | C12: 10.7 | D12: 10.78 | E12: 10.86 | F12: 10.94 | G12: 11.02 | H12: 11.11 | I12: 11.19 | J12: 11.28 | K12: 11.38 | L12: 11.44 | M12: 11.5 | N12: 11.56 | O12: 11.62 | P12: 11.67 | Q12: 11.72 | R12: 11.77 | S12: 11.82 | T12: 11.87 | U12: 11.91 | V12: 11.96 | W12: 12 | X12: 12.05 | Y12: 12.09
A13: Total | B13: 100 | C13: 100 | D13: 100 | E13: 100 | F13: 100 | G13: 100 | H13: 100 | I13: 100 | J13: 100 | K13: 100 | L13: 100 | M13: 100 | N13: 100 | O13: 100 | P13: 100 | Q13: 100 | R13: 100 | S13: 100 | T13: 100 | U13: 100 | V13: 100 | W13: 100 | X13: 100 | Y13: 100
D21: .

Sheet Povincial est by age and sex
B1: EC | E1: FS | H1: GP | K1: KZN | N1: LIM | Q1: MP | T1: NC | W1: NW | Z1: WC | AC1: RSA
B2: Male | C2: Female | D2: Total | E2: Male | F2: Female | G2: Total | H2: Male | I2: Female | J2: Total | K2: Male | L2: Female | M2: Total | N2: Male | O2: Female | P2: Total | Q2: Male | R2: Female | S2: Total | T2: Male | U2: Female | V2: Total | W2: Male | X2: Female | Y2: Total | Z2: Male | AA2: Female | AB2: Total | AC2: Male | AD2: Female | AE2: Total
A3: 0-4 | B3: 353344 | C3: 347608 | D3: 700952 | E3: 134896 | F3: 133750 | G3: 268645 | H3: 597120 | I3: 581654 | J3: 1178774 | K3: 601187 | L3: 585290 | M3: 1186477 | N3: 343745 | O3: 334984 | P3: 678729 | Q3: 231066 | R3: 226456 | S3: 457522 | T3: 66728 | U3: 65528 | V3: 132257 | W3: 190047 | X3: 185456 | Y3: 375503 | Z3: 271995 | AA3: 262147 | AB3: 534142 | AC3: 2790128 | AD3: 2722873 | AE3: 5513001 | AF3: ='MYPE by pop grp age and sex'!P3-'Povincial est by age and sex'!AE3 -> 0
A4: 5-9 | B4: 353590 | C4: 349708 | D4: 703298 | E4: 130025 | F4: 130124 | G4: 260150 | H4: 590445 | I4: 573174 | J4: 1163619 | K4: 580138 | L4: 564768 | M4: 1144907 | N4: 338812 | O4: 330157 | P4: 668969 | Q4: 219453 | R4: 216180 | S4: 435633 | T4: 63777 | U4: 63078 | V4: 126855 | W4: 182203 | X4: 176595 | Y4: 358799 | Z4: 271843 | AA4: 261468 | AB4: 533310 | AC4: 2730286 | AD4: 2665253 | AE4: 5395539 | AF4: ='MYPE by pop grp age and sex'!P4-'Povincial est by age and sex'!AE4 -> 0
A5: 10-14 | B5: 371215 | C5: 367777 | D5: 738992 | E5: 136378 | F5: 138338 | G5: 274716 | H5: 606347 | I5: 590766 | J5: 1197113 | K5: 597072 | L5: 584171 | M5: 1181243 | N5: 341170 | O5: 332353 | P5: 673523 | Q5: 227683 | R5: 225517 | S5: 453201 | T5: 63882 | U5: 63539 | V5: 127421 | W5: 191394 | X5: 186904 | Y5: 378298 | Z5: 296137 | AA5: 286324 | AB5: 582460 | AC5: 2831278 | AD5: 2775688 | AE5: 5606966 | AF5: ='MYPE by pop grp age and sex'!P5-'Povincial est by age and sex'!AE5 -> 0
A6: 15-19 | B6: 344512 | C6: 346393 | D6: 690905 | E6: 138465 | F6: 144094 | G6: 282559 | H6: 613634 | I6: 602693 | J6: 1216327 | K6: 573566 | L6: 568576 | M6: 1142142 | N6: 312773 | O6: 301784 | P6: 614557 | Q6: 228407 | R6: 227295 | S6: 455702 | T6: 60896 | U6: 60072 | V6: 120968 | W6: 189615 | X6: 185982 | Y6: 375597 | Z6: 305565 | AA6: 295914 | AB6: 601478 | AC6: 2767432 | AD6: 2732803 | AE6: 5500235 | AF6: ='MYPE by pop grp age and sex'!P6-'Povincial est by age and sex'!AE6 -> 0
A7: 20-24 | B7: 250964 | C7: 270523 | D7: 521487 | E7: 116679 | F7: 124544 | G7: 241223 | H7: 607225 | I7: 581979 | J7: 1189204 | K7: 481166 | L7: 488768 | M7: 969934 | N7: 245984 | O7: 241065 | P7: 487049 | Q7: 194909 | R7: 194051 | S7: 388960 | T7: 54018 | U7: 52047 | V7: 106064 | W7: 167827 | X7: 159391 | Y7: 327217 | Z7: 288644 | AA7: 273260 | AB7: 561903 | AC7: 2407414 | AD7: 2385627 | AE7: 4793041 | AF7: ='MYPE by pop grp age and sex'!P7-'Povincial est by age and sex'!AE7 -> 0
A8: 25-29 | B8: 228276 | C8: 252547 | D8: 480823 | E8: 112827 | F8: 120558 | G8: 233385 | H8: 681881 | I8: 646514 | J8: 1328394 | K8: 493452 | L8: 508793 | M8: 1002245 | N8: 229002 | O8: 228771 | P8: 457773 | Q8: 213076 | R8: 209622 | S8: 422698 | T8: 54238 | U8: 51274 | V8: 105512 | W8: 173221 | X8: 154422 | Y8: 327642 | Z8: 314930 | AA8: 292824 | AB8: 607754 | AC8: 2500901 | AD8: 2465326 | AE8: 4966227 | AF8: ='MYPE by pop grp age and sex'!P8-'Povincial est by age and sex'!AE8 -> 0
A9: 30-34 | B9: 252043 | C9: 283608 | D9: 535651 | E9: 120006 | F9: 128855 | G9: 248861 | H9: 783517 | I9: 756404 | J9: 1539921 | K9: 530399 | L9: 549630 | M9: 1080029 | N9: 252364 | O9: 252811 | P9: 505175 | Q9: 231566 | R9: 222173 | S9: 453739 | T9: 57859 | U9: 54237 | V9: 112096 | W9: 191929 | X9: 168844 | Y9: 360773 | Z9: 342348 | AA9: 325679 | AB9: 668027 | AC9: 2762030 | AD9: 2742243 | AE9: 5504273 | AF9: ='MYPE by pop grp age and sex'!P9-'Povincial est by age and sex'!AE9 -> 0
A10: 35-39 | B10: 241879 | C10: 269823 | D10: 511702 | E10: 122777 | F10: 132272 | G10: 255049 | H10: 849953 | I10: 823533 | J10: 1673486 | K10: 520679 | L10: 531072 | M10: 1051750 | N10: 244388 | O10: 241721 | P10: 486108 | Q10: 240024 | R10: 223255 | S10: 463279 | T10: 58398 | U10: 54539 | V10: 112937 | W10: 196639 | X10: 172612 | Y10: 369251 | Z10: 361259 | AA10: 348798 | AB10: 710057 | AC10: 2835996 | AD10: 2797625 | AE10: 5633621 | AF10: ='MYPE by pop grp age and sex'!P10-'Povincial est by age and sex'!AE10 -> 0
A11: 40-44 | B11: 194587 | C11: 211287 | D11: 405875 | E11: 99214 | F11: 107650 | G11: 206864 | H11: 711909 | I11: 696562 | J11: 1408472 | K11: 400198 | L11: 422251 | M11: 822450 | N11: 197186 | O11: 192372 | P11: 389558 | Q11: 200571 | R11: 180221 | S11: 380792 | T11: 49323 | U11: 43760 | V11: 93083 | W11: 163250 | X11: 138434 | Y11: 301684 | Z11: 314250 | AA11: 303064 | AB11: 617314 | AC11: 2330489 | AD11: 2295603 | AE11: 4626092 | AF11: ='MYPE by pop grp age and sex'!P11-'Povincial est by age and sex'!AE11 -> 0
A12: 45-49 | B12: 154448 | C12: 172625 | D12: 327073 | E12: 75868 | F12: 86004 | G12: 161872 | H12: 552894 | I12: 499342 | J12: 1052236 | K12: 284267 | L12: 318524 | M12: 602791 | N12: 145254 | O12: 166031 | P12: 311285 | Q12: 143865 | R12: 138649 | S12: 282514 | T12: 38109 | U12: 34180 | V12: 72289 | W12: 127191 | X12: 109470 | Y12: 236660 | Z12: 245695 | AA12: 237211 | AB12: 482906 | AC12: 1767591 | AD12: 1762035 | AE12: 3529626 | AF12: ='MYPE by pop grp age and sex'!P12-'Povincial est by age and sex'!AE12 -> 0
A13: 50-54 | B13: 129990 | C13: 164761 | D13: 294750 | E13: 64407 | F13: 78328 | G13: 142734 | H13: 453471 | I13: 391280 | J13: 844751 | K13: 230295 | L13: 278227 | M13: 508522 | N13: 114283 | O13: 148963 | P13: 263246 | Q13: 110653 | R13: 120249 | S13: 230901 | T13: 31402 | U13: 31122 | V13: 62524 | W13: 101944 | X13: 96587 | Y13: 198532 | Z13: 213396 | AA13: 208662 | AB13: 422059 | AC13: 1449841 | AD13: 1518177 | AE13: 2968018 | AF13: ='MYPE by pop grp age and sex'!P13-'Povincial est by age and sex'!AE13 -> 0
A14: 55-59 | B14: 102641 | C14: 159117 | D14: 261757 | E14: 52193 | F14: 72939 | G14: 125132 | H14: 338006 | I14: 334189 | J14: 672195 | K14: 166092 | L14: 245857 | M14: 411948 | N14: 86065 | O14: 129047 | P14: 215112 | Q14: 81985 | R14: 104359 | S14: 186344 | T14: 24735 | U14: 29196 | V14: 53932 | W14: 80513 | X14: 84356 | Y14: 164868 | Z14: 172470 | AA14: 195462 | AB14: 367932 | AC14: 1104699 | AD14: 1354521 | AE14: 2459220 | AF14: ='MYPE by pop grp age and sex'!P14-'Povincial est by age and sex'!AE14 -> 0
... A20: Total | B20: 3293541 | C20: 3797247 | D20: 7090788 | E20: 1426903 | F20: 1612930 | G20: 3039834 | H20: 8136465 | I20: 7968469 | J20: 16104933 | K20: 5851546 | L20: 6380702 | M20: 12232247 | N20: 3044504 | O20: 3321688 | P20: 6366192 | Q20: 2507173 | R20: 2568960 | S20: 5076133 | T20: 682131 | U20: 697052 | V20: 1379183 | W20: 2126796 | X20: 2057151 | Y20: 4183947 | Z20: 3803047 | AA20: 3824641 | AB20: 7627688 | AC20: 30872106 | AD20: 32228839 | AE20: 63100945 | AF20: ='MYPE by pop grp age and sex'!P20-'Povincial est by age and sex'!AE20 -> 0
AC21: ='MYPE by pop grp age and sex'!N20-'Povincial est by age and sex'!AC20 -> 0 | AD21: ='MYPE by pop grp age and sex'!O20-'Povincial est by age and sex'!AD20 -> 0 | AE21: ='MYPE by pop grp age and sex'!P20-'Povincial est by age and sex'!AE20 -> 0
A22: in thousands | B22: =B1 -> EC | E22: =E1 -> FS | H22: =H1 -> GP | K22: =K1 -> KZN | N22: =N1 -> LIM | Q22: =Q1 -> MP | T22: =T1 -> NC | W22: =W1 -> NW | Z22: =Z1 -> WC | AC22: =AC1 -> RSA
B23: =B2 -> Male | C23: =C2 -> Female | D23: =D2 -> Total | E23: =E2 -> Male | F23: =F2 -> Female | G23: =G2 -> Total | H23: =H2 -> Male | I23: =I2 -> Female | ... AE23: =AE2 -> Total
A24: =A3 -> 0-4 | B24: =ROUND(B3/1000,1) -> 353.3 | C24: =ROUND(C3/1000,1) -> 347.6 | D24: =ROUND(D3/1000,1) -> 701 | E24: =ROUND(E3/1000,1) -> 134.9 | F24: =ROUND(F3/1000,1) -> 133.8 | G24: =ROUND(G3/1000,1) -> 268.6 | H24: =ROUND(H3/1000,1) -> 597.1 | I24: =ROUND(I3/1000,1) -> 581.7 | ... AE24: =ROUND(AE3/1000,1) -> 5513
A25: =A4 -> 5-9 | B25: =ROUND(B4/1000,1) -> 353.6 | C25: =ROUND(C4/1000,1) -> 349.7 | D25: =ROUND(D4/1000,1) -> 703.3 | E25: =ROUND(E4/1000,1) -> 130 | F25: =ROUND(F4/1000,1) -> 130.1 | G25: =ROUND(G4/1000,1) -> 260.2 | H25: =ROUND(H4/1000,1) -> 590.4 | I25: =ROUND(I4/1000,1) -> 573.2 | ... AE25: =ROUND(AE4/1000,1) -> 5395.5
A26: =A5 -> 10-14 | B26: =ROUND(B5/1000,1) -> 371.2 | C26: =ROUND(C5/1000,1) -> 367.8 | D26: =ROUND(D5/1000,1) -> 739 | E26: =ROUND(E5/1000,1) -> 136.4 | F26: =ROUND(F5/1000,1) -> 138.3 | G26: =ROUND(G5/1000,1) -> 274.7 | H26: =ROUND(H5/1000,1) -> 606.3 | I26: =ROUND(I5/1000,1) -> 590.8 | ... AE26: =ROUND(AE5/1000,1) -> 5607
A27: =A6 -> 15-19 | B27: =ROUND(B6/1000,1) -> 344.5 | C27: =ROUND(C6/1000,1) -> 346.4 | D27: =ROUND(D6/1000,1) -> 690.9 | E27: =ROUND(E6/1000,1) -> 138.5 | F27: =ROUND(F6/1000,1) -> 144.1 | G27: =ROUND(G6/1000,1) -> 282.6 | H27: =ROUND(H6/1000,1) -> 613.6 | I27: =ROUND(I6/1000,1) -> 602.7 | ... AE27: =ROUND(AE6/1000,1) -> 5500.2
A28: =A7 -> 20-24 | B28: =ROUND(B7/1000,1) -> 251 | C28: =ROUND(C7/1000,1) -> 270.5 | D28: =ROUND(D7/1000,1) -> 521.5 | E28: =ROUND(E7/1000,1) -> 116.7 | F28: =ROUND(F7/1000,1) -> 124.5 | G28: =ROUND(G7/1000,1) -> 241.2 | H28: =ROUND(H7/1000,1) -> 607.2 | I28: =ROUND(I7/1000,1) -> 582 | ... AE28: =ROUND(AE7/1000,1) -> 4793
A29: =A8 -> 25-29 | B29: =ROUND(B8/1000,1) -> 228.3 | C29: =ROUND(C8/1000,1) -> 252.5 | D29: =ROUND(D8/1000,1) -> 480.8 | E29: =ROUND(E8/1000,1) -> 112.8 | F29: =ROUND(F8/1000,1) -> 120.6 | G29: =ROUND(G8/1000,1) -> 233.4 | H29: =ROUND(H8/1000,1) -> 681.9 | I29: =ROUND(I8/1000,1) -> 646.5 | ... AE29: =ROUND(AE8/1000,1) -> 4966.2
A30: =A9 -> 30-34 | B30: =ROUND(B9/1000,1) -> 252 | C30: =ROUND(C9/1000,1) -> 283.6 | D30: =ROUND(D9/1000,1) -> 535.7 | E30: =ROUND(E9/1000,1) -> 120 | F30: =ROUND(F9/1000,1) -> 128.9 | G30: =ROUND(G9/1000,1) -> 248.9 | H30: =ROUND(H9/1000,1) -> 783.5 | I30: =ROUND(I9/1000,1) -> 756.4 | ... AE30: =ROUND(AE9/1000,1) -> 5504.3
A31: =A10 -> 35-39 | B31: =ROUND(B10/1000,1) -> 241.9 | C31: =ROUND(C10/1000,1) -> 269.8 | D31: =ROUND(D10/1000,1) -> 511.7 | E31: =ROUND(E10/1000,1) -> 122.8 | F31: =ROUND(F10/1000,1) -> 132.3 | G31: =ROUND(G10/1000,1) -> 255 | H31: =ROUND(H10/1000,1) -> 850 | I31: =ROUND(I10/1000,1) -> 823.5 | ... AE31: =ROUND(AE10/1000,1) -> 5633.6
A32: =A11 -> 40-44 | B32: =ROUND(B11/1000,1) -> 194.6 | C32: =ROUND(C11/1000,1) -> 211.3 | D32: =ROUND(D11/1000,1) -> 405.9 | E32: =ROUND(E11/1000,1) -> 99.2 | F32: =ROUND(F11/1000,1) -> 107.7 | G32: =ROUND(G11/1000,1) -> 206.9 | H32: =ROUND(H11/1000,1) -> 711.9 | I32: =ROUND(I11/1000,1) -> 696.6 | ... AE32: =ROUND(AE11/1000,1) -> 4626.1
A33: =A12 -> 45-49 | B33: =ROUND(B12/1000,1) -> 154.4 | C33: =ROUND(C12/1000,1) -> 172.6 | D33: =ROUND(D12/1000,1) -> 327.1 | E33: =ROUND(E12/1000,1) -> 75.9 | F33: =ROUND(F12/1000,1) -> 86 | G33: =ROUND(G12/1000,1) -> 161.9 | H33: =ROUND(H12/1000,1) -> 552.9 | I33: =ROUND(I12/1000,1) -> 499.3 | ... AE33: =ROUND(AE12/1000,1) -> 3529.6
A34: =A13 -> 50-54 | B34: =ROUND(B13/1000,1) -> 130 | C34: =ROUND(C13/1000,1) -> 164.8 | D34: =ROUND(D13/1000,1) -> 294.8 | E34: =ROUND(E13/1000,1) -> 64.4 | F34: =ROUND(F13/1000,1) -> 78.3 | G34: =ROUND(G13/1000,1) -> 142.7 | H34: =ROUND(H13/1000,1) -> 453.5 | I34: =ROUND(I13/1000,1) -> 391.3 | ... AE34: =ROUND(AE13/1000,1) -> 2968
A35: =A14 -> 55-59 | B35: =ROUND(B14/1000,1) -> 102.6 | C35: =ROUND(C14/1000,1) -> 159.1 | D35: =ROUND(D14/1000,1) -> 261.8 | E35: =ROUND(E14/1000,1) -> 52.2 | F35: =ROUND(F14/1000,1) -> 72.9 | G35: =ROUND(G14/1000,1) -> 125.1 | H35: =ROUND(H14/1000,1) -> 338 | I35: =ROUND(I14/1000,1) -> 334.2 | ... AE35: =ROUND(AE14/1000,1) -> 2459.2
... A40: =A19 -> 80+ | B40: =ROUND(B19/1000,1) -> 56.6 | C40: =ROUND(C19/1000,1) -> 112.1 | D40: =ROUND(D19/1000,1) -> 168.7 | E40: =ROUND(E19/1000,1) -> 7.9 | F40: =ROUND(F19/1000,1) -> 25 | G40: =ROUND(G19/1000,1) -> 32.9 | H40: =ROUND(H19/1000,1) -> 43.9 | I40: =ROUND(I19/1000,1) -> 77.2 | ... AE40: =ROUND(AE19/1000,1) -> 705
B41: =ROUND(B20/1000,1) -> 3293.5 | C41: =ROUND(C20/1000,1) -> 3797.2 | D41: =ROUND(D20/1000,1) -> 7090.8 | E41: =ROUND(E20/1000,1) -> 1426.9 | F41: =ROUND(F20/1000,1) -> 1612.9 | G41: =ROUND(G20/1000,1) -> 3039.8 | H41: =ROUND(H20/1000,1) -> 8136.5 | I41: =ROUND(I20/1000,1) -> 7968.5 | ... AE41: =ROUND(AE20/1000,1) -> 63100.9

Sheet TFR by Province
C1: Figure 1 Provincial Average Total Fertilty Rate
C2: EC | D2: FS | E2: GP | F2: KZN | G2: LP | H2: MP | I2: NC | J2: NW | K2: WC
B3: 2001-2006 | C3: 3.15 | D3: 2.74 | E3: 2.24 | F3: 2.9 | G3: 3.26 | H3: 2.8 | I3: 3.04 | J3: 3.1 | K3: 2.27
B4: 2006-2011 | C4: 3.2 | D4: 2.84 | E4: 2.35 | F4: 2.93 | G4: 3.32 | H4: 2.91 | I4: 3.09 | J4: 3.18 | K4: 2.37
B5: 2011-2016 | C5: 2.97 | D5: 2.45 | E5: 1.96 | F5: 2.61 | G5: 3.22 | H5: 2.46 | I5: 2.9 | J5: 2.73 | K5: 2.06
B6: 2016-2021 | C6: 2.76 | D6: 2.29 | E6: 1.82 | F6: 2.44 | G6: 3.07 | H6: 2.29 | I6: 2.74 | J6: 2.46 | K6: 1.83
B7: 2021-2026 | C7: 2.65 | D7: 2.22 | E7: 1.72 | F7: 2.39 | G7: 2.94 | H7: 2.25 | I7: 2.64 | J7: 2.41 | K7: 1.79

Sheet LE by gender and prov
B2: LE-Males
C4: EC | D4: FS | E4: GP | F4: KZN | G4: LP | H4: MP | I4: NC | J4: NW | K4: WC
B5: 2001-2006 | C5: 51.4 | D5: 43.1 | E5: 54.8 | F5: 45.5 | G5: 52.8 | H5: 50.7 | I5: 49.8 | J5: 45.8 | K5: 58.2
B6: 2006-2011 | C6: 54.1 | D6: 46 | E6: 57.3 | F6: 48.7 | G6: 55 | H6: 53.5 | I6: 51.5 | J6: 49 | K6: 61.3
B7: 2011-2016 | C7: 59.6 | D7: 54.5 | E7: 62.8 | F7: 56.7 | G7: 60.3 | H7: 59.9 | I7: 57.6 | J7: 56.8 | K7: 65
B8: 2016-2021 | C8: 60 | D8: 55.5 | E8: 63.5 | F8: 57.5 | G8: 61.5 | H8: 61.1 | I8: 57.9 | J8: 57.6 | K8: 66
B9: 2021-2026 | C9: 61.5 | D9: 57.3 | E9: 65.3 | F9: 59.3 | G9: 64 | H9: 62.8 | I9: 59.5 | J9: 59.7 | K9: 67.6
B10: LE-Females
C11: EC | D11: FS | E11: GP | F11: KZN | G11: LP | H11: MP | I11: NC | J11: NW | K11: WC
B12: 2001-2006 | C12: 55.9 | D12: 48.2 | E12: 59.7 | F12: 50.6 | G12: 57.3 | H12: 55.1 | I12: 55 | J12: 50.7 | K12: 62.6
B13: 2006-2011 | C13: 59.2 | D13: 52.5 | E13: 62.5 | F13: 54.3 | G13: 60.1 | H13: 58.3 | I13: 57.8 | J13: 54.7 | K13: 65.6
B14: 2011-2016 | C14: 65 | D14: 61.4 | E14: 68.4 | F14: 63.2 | G14: 66 | H14: 65.1 | I14: 64 | J14: 63.3 | K14: 69.7
B15: 2016-2021 | C15: 65.7 | D15: 62.4 | E15: 69.1 | F15: 63.8 | G15: 66.5 | H15: 66.4 | I15: 64.7 | J15: 64 | K15: 71.2
B16: 2021-2026 | C16: 67.6 | D16: 64.2 | E16: 71.2 | F16: 65.4 | G16: 68.7 | H16: 67.7 | I16: 66.2 | J16: 66 | K16: 72.2

Sheet %children over time within prov
B1: % of Children under 15 within each province
B2: 2002 | C2: 2003 | D2: 2004 | E2: 2005 | F2: 2006 | G2: 2007 | H2: 2008 | I2: 2009 | J2: 2010 | K2: 2011 | L2: 2012 | M2: 2013 | N2: 2014 | O2: 2015 | P2: 2016 | Q2: 2017 | R2: 2018 | S2: 2019 | T2: 2020 | U2: 2021 | V2: 2022 | W2: 2023 | X2: 2024 | Y2: 2025
A3: Eastern Cape | B3: 36.8 | C3: 35.8 | D3: 34.9 | E3: 34.3 | F3: 33.7 | G3: 33.2 | H3: 32.8 | I3: 32.5 | J3: 32.1 | K3: 31.9 | L3: 31.7 | M3: 31.7 | N3: 31.7 | O3: 31.7 | P3: 31.7 | Q3: 31.6 | R3: 31.6 | S3: 31.5 | T3: 31.4 | U3: 31.3 | V3: 31.1 | W3: 30.8 | X3: 30.5 | Y3: 30.2 | Z3: 13.148862
A4: Free State | B4: 31.3 | C4: 30.6 | D4: 30.1 | E4: 29.7 | F4: 29.4 | G4: 29.2 | H4: 29 | I4: 29 | J4: 28.9 | K4: 28.9 | L4: 28.8 | M4: 28.8 | N4: 28.7 | O4: 28.6 | P4: 28.4 | Q4: 28.2 | R4: 28.1 | S4: 28 | T4: 27.8 | U4: 27.6 | V4: 27.4 | W4: 27.1 | X4: 26.7 | Y4: 26.4 | Z4: 4.9171689
A5: Gauteng | B5: 24.7 | C5: 24.2 | D5: 23.8 | E5: 23.5 | F5: 23.4 | G5: 23.3 | H5: 23.3 | I5: 23.3 | J5: 23.4 | K5: 23.4 | L5: 23.6 | M5: 23.7 | N5: 23.7 | O5: 23.7 | P5: 23.7 | Q5: 23.6 | R5: 23.6 | S5: 23.5 | T5: 23.4 | U5: 23.3 | V5: 23.1 | W5: 22.7 | X5: 22.3 | Y5: 22 | Z5: 21.330739
A6: KwaZulu-Natal | B6: 35.4 | C6: 34.6 | D6: 34 | E6: 33.4 | F6: 32.9 | G6: 32.4 | H6: 32 | I6: 31.7 | J6: 31.4 | K6: 31.2 | L6: 31 | M6: 30.8 | N6: 30.7 | O6: 30.5 | P6: 30.3 | Q6: 30.2 | R6: 30.2 | S6: 30.1 | T6: 29.9 | U6: 29.8 | V6: 29.6 | W6: 29.3 | X6: 29 | Y6: 28.7 | Z6: 21.203463
A7: Limpopo | B7: 39.4 | C7: 38.4 | D7: 37.5 | E7: 36.8 | F7: 36.3 | G7: 35.7 | H7: 35.2 | I7: 34.7 | J7: 34.3 | K7: 33.9 | L7: 33.6 | M7: 33.5 | N7: 33.5 | O7: 33.4 | P7: 33.3 | Q7: 33.2 | R7: 33.2 | S7: 33.1 | T7: 32.9 | U7: 32.8 | V7: 32.6 | W7: 32.3 | X7: 32 | Y7: 31.7 | Z7: 12.180969
A8: Mpumalanga | B8: 36.3 | C8: 35.3 | D8: 34.4 | E8: 33.6 | F8: 32.9 | G8: 32.2 | H8: 31.8 | I8: 31.4 | J8: 31.1 | K8: 30.8 | L8: 30.5 | M8: 30.3 | N8: 29.9 | O8: 29.5 | P8: 29.1 | Q8: 28.7 | R8: 28.6 | S8: 28.5 | T8: 28.2 | U8: 28 | V8: 27.7 | W8: 27.3 | X8: 26.9 | Y8: 26.5 | Z8: 8.1564967
A9: Northern Cape | B9: 32.6 | C9: 31.9 | D9: 31.4 | E9: 31 | F9: 30.7 | G9: 30.4 | H9: 30.2 | I9: 30.1 | J9: 30 | K9: 29.9 | L9: 29.8 | M9: 29.8 | N9: 29.7 | O9: 29.6 | P9: 29.5 | Q9: 29.4 | R9: 29.3 | S9: 29.2 | T9: 29 | U9: 28.9 | V9: 28.7 | W9: 28.5 | X9: 28.2 | Y9: 28 | Z9: 2.3223607
A10: North West | B10: 31.7 | C10: 31.1 | D10: 30.6 | E10: 30.3 | F10: 30.1 | G10: 29.9 | H10: 29.8 | I10: 29.8 | J10: 29.7 | K10: 29.7 | L10: 29.6 | M10: 29.6 | N10: 29.6 | O10: 29.4 | P10: 29.2 | Q10: 29 | R10: 28.9 | S10: 28.6 | T10: 28.3 | U10: 28.1 | V10: 27.7 | W10: 27.3 | X10: 26.9 | Y10: 26.6 | Z10: 6.7151931
A11: Western Cape | B11: 27.8 | C11: 27.2 | D11: 26.7 | E11: 26.3 | F11: 25.9 | G11: 25.6 | H11: 25.4 | I11: 25.3 | J11: 25.1 | K11: 25.1 | L11: 25 | M11: 24.9 | N11: 24.8 | O11: 24.5 | P11: 24.3 | Q11: 24.1 | R11: 23.9 | S11: 23.7 | T11: 23.4 | U11: 23.2 | V11: 22.9 | W11: 22.4 | X11: 22 | Y11: 21.6 | Z11: 10.024748
A12: National | B12: 32.6 | C12: 31.8 | D12: 31.1 | E12: 30.6 | F12: 30.1 | G12: 29.8 | H12: 29.5 | I12: 29.2 | J12: 29 | K12: 28.8 | L12: 28.7 | M12: 28.6 | N12: 28.5 | O12: 28.4 | P12: 28.2 | Q12: 28 | R12: 28 | S12: 27.9 | T12: 27.7 | U12: 27.5 | V12: 27.2 | W12: 26.9 | X12: 26.5 | Y12: 26.2 | Z12: 100

Sheet %elderly overtime within prov
B1: % of elderly within each province
B2: 2002 | C2: 2003 | D2: 2004 | E2: 2005 | F2: 2006 | G2: 2007 | H2: 2008 | I2: 2009 | J2: 2010 | K2: 2011 | L2: 2012 | M2: 2013 | N2: 2014 | O2: 2015 | P2: 2016 | Q2: 2017 | R2: 2018 | S2: 2019 | T2: 2020 | U2: 2021 | V2: 2022 | W2: 2023 | X2: 2024 | Y2: 2025
A3: Eastern Cape | B3: 9.6 | C3: 9.7 | D3: 9.8 | E3: 9.9 | F3: 9.9 | G3: 10 | H3: 10.1 | I3: 10.2 | J3: 10.4 | K3: 10.5 | L3: 10.7 | M3: 10.9 | N3: 11.1 | O3: 11.2 | P3: 11.4 | Q3: 11.6 | R3: 11.8 | S3: 12 | T3: 12.2 | U3: 12.3 | V3: 12.5 | W3: 12.6 | X3: 12.8 | Y3: 12.9
A4: Free State | B4: 7.7 | C4: 7.8 | D4: 7.9 | E4: 8.1 | F4: 8.3 | G4: 8.4 | H4: 8.6 | I4: 8.8 | J4: 8.9 | K4: 9 | L4: 9.2 | M4: 9.3 | N4: 9.5 | O4: 9.7 | P4: 9.9 | Q4: 10.1 | R4: 10.2 | S4: 10.4 | T4: 10.5 | U4: 10.6 | V4: 10.7 | W4: 10.8 | X4: 11 | Y4: 11.1
A5: Gauteng | B5: 6.5 | C5: 6.6 | D5: 6.6 | E5: 6.7 | F5: 6.9 | G5: 7 | H5: 7.1 | I5: 7.2 | J5: 7.3 | K5: 7.4 | L5: 7.6 | M5: 7.7 | N5: 7.9 | O5: 8.1 | P5: 8.3 | Q5: 8.5 | R5: 8.7 | S5: 8.9 | T5: 9.1 | U5: 9.3 | V5: 9.5 | W5: 9.7 | X5: 10 | Y5: 10.2
A6: KwaZulu-Natal | B6: 7.3 | C6: 7.3 | D6: 7.4 | E6: 7.5 | F6: 7.6 | G6: 7.7 | H6: 7.8 | I6: 7.9 | J6: 8 | K6: 8.1 | L6: 8.2 | M6: 8.3 | N6: 8.4 | O6: 8.5 | P6: 8.6 | Q6: 8.7 | R6: 8.7 | S6: 8.8 | T6: 8.9 | U6: 8.9 | V6: 9 | W6: 9.1 | X6: 9.2 | Y6: 9.2
A7: Limpopo | B7: 8 | C7: 8 | D7: 8 | E7: 8 | F7: 8 | G7: 8 | H7: 8 | I7: 8.1 | J7: 8.2 | K7: 8.3 | L7: 8.3 | M7: 8.4 | N7: 8.5 | O7: 8.6 | P7: 8.7 | Q7: 8.8 | R7: 8.9 | S7: 9 | T7: 9.1 | U7: 9.1 | V7: 9.2 | W7: 9.4 | X7: 9.5 | Y7: 9.7
A8: Mpumalanga | B8: 6.6 | C8: 6.6 | D8: 6.7 | E8: 6.7 | F8: 6.7 | G8: 6.8 | H8: 6.9 | I8: 6.9 | J8: 7 | K8: 7.2 | L8: 7.3 | M8: 7.4 | N8: 7.6 | O8: 7.7 | P8: 7.9 | Q8: 8 | R8: 8.1 | S8: 8.3 | T8: 8.4 | U8: 8.5 | V8: 8.6 | W8: 8.8 | X8: 9 | Y8: 9.2
A9: Northern Cape | B9: 8.4 | C9: 8.5 | D9: 8.6 | E9: 8.7 | F9: 8.8 | G9: 8.9 | H9: 9 | I9: 9.1 | J9: 9.2 | K9: 9.2 | L9: 9.4 | M9: 9.5 | N9: 9.7 | O9: 9.8 | P9: 10 | Q9: 10.2 | R9: 10.3 | S9: 10.5 | T9: 10.6 | U9: 10.7 | V9: 10.8 | W9: 10.9 | X9: 11 | Y9: 11.1
A10: North West | B10: 7.9 | C10: 7.9 | D10: 8 | E10: 8.1 | F10: 8.1 | G10: 8.1 | H10: 8.1 | I10: 8.1 | J10: 8.1 | K10: 8.1 | L10: 8.2 | M10: 8.2 | N10: 8.3 | O10: 8.4 | P10: 8.6 | Q10: 8.7 | R10: 8.9 | S10: 9 | T10: 9.2 | U10: 9.2 | V10: 9.3 | W10: 9.5 | X10: 9.6 | Y10: 9.8
A11: Western Cape | B11: 8.2 | C11: 8.2 | D11: 8.2 | E11: 8.3 | F11: 8.4 | G11: 8.5 | H11: 8.5 | I11: 8.6 | J11: 8.7 | K11: 8.8 | L11: 9 | M11: 9.1 | N11: 9.3 | O11: 9.5 | P11: 9.7 | Q11: 10 | R11: 10.3 | S11: 10.6 | T11: 10.9 | U11: 11.1 | V11: 11.4 | W11: 11.7 | X11: 12 | Y11: 12.3
A12: National | B12: 7.7 | C12: 7.7 | D12: 7.8 | E12: 7.8 | F12: 7.9 | G12: 8 | H12: 8.1 | I12: 8.2 | J12: 8.3 | K12: 8.4 | L12: 8.5 | M12: 8.6 | N12: 8.7 | O12: 8.9 | P12: 9.1 | Q12: 9.2 | R12: 9.4 | S12: 9.5 | T12: 9.7 | U12: 9.8 | V12: 9.9 | W12: 10.1 | X12: 10.3 | Y12: 10.5

Sheet Selected ages
B1: National | D1: EC | F1: FS | H1: GP | J1: KZN | L1: LIM | N1: MP | P1: NC | R1: NW | T1: WC
B2: Male | C2: Female | D2: Male | E2: Female | F2: Male | G2: Female | H2: Male | I2: Female | J2: Male | K2: Female | L2: Male | M2: Female | N2: Male | O2: Female | P2: Male | Q2: Female | R2: Male | S2: Female | T2: Male | U2: Female
A3: 18-34 | B3: 8749922 | C3: 8661123 | D3: 860005.12 | E3: 938623.18 | F3: 403424.54 | G3: 430552.77 | H3: 2320668.7 | I3: 2226935.8 | J3: 1726192.5 | K3: 1767856.2 | L3: 846581.49 | M3: 837923.48 | N3: 727609.45 | O3: 713522.52 | P3: 190060.29 | Q3: 181017.13 | R3: 607480.35 | S3: 555414.85 | T3: 1067899.5 | U3: 1009277.1
A4: 35-49 | B4: 6934076 | C4: 6855263 | D4: 590914.26 | E4: 653735.55 | F4: 297859.36 | G4: 325926.49 | H4: 2114756.8 | I4: 2019437.1 | J4: 1205144 | K4: 1271847.1 | L4: 586827.9 | M4: 600123.57 | N4: 584459.93 | O4: 542125.26 | P4: 145829.59 | Q4: 132478.84 | R4: 487079.49 | S4: 420515.87 | T4: 921204.71 | U4: 889073.2
A5: 50-64 | B5: 3462145 | C5: 4099972 | D5: 322441.59 | E5: 481400.08 | F5: 160721.39 | G5: 216787.97 | H5: 1064974.8 | I5: 1015759.3 | J5: 534742.53 | K5: 755100.47 | L5: 268087.33 | M5: 399134.68 | N5: 259203.08 | O5: 315034.04 | P5: 75831.476 | Q5: 86502.985 | R5: 250124.88 | S5: 254563.87 | T5: 526017.89 | U5: 575688.64
A6: 65+ | B6: 1686416 | C6: 2783791 | D6: 226240.98 | E6: 443947.67 | F6: 79046.035 | G6: 149952.71 | H6: 476564.74 | I6: 600087.99 | J6: 254680.68 | K6: 503757.16 | L6: 125737.4 | M6: 300505.41 | N6: 117352.56 | O6: 190504.69 | P6: 39072.327 | Q6: 68294.416 | R6: 103356.36 | S6: 164476.62 | T6: 264364.91 | U6: 362264.33
